2025-04-21 16:05:40,107 INFO: project_flask startup [in /var/www/project_flask/app/__init__.py:93]
2025-04-21 16:05:40,216 INFO: project_flask startup [in /var/www/project_flask/app/__init__.py:93]
2025-04-21 16:31:03,819 INFO: project_flask startup [in /var/www/project_flask/app/__init__.py:93]
2025-04-21 16:37:48,488 INFO: project_flask startup [in /var/www/project_flask/app/__init__.py:93]
2025-04-21 16:37:48,525 INFO: project_flask startup [in /var/www/project_flask/app/__init__.py:93]
2025-04-21 16:37:48,590 INFO: project_flask startup [in /var/www/project_flask/app/__init__.py:93]
2025-04-21 16:40:14,327 INFO: project_flask startup [in /var/www/project_flask/app/__init__.py:93]
2025-04-21 16:45:21,086 INFO: project_flask startup [in /var/www/project_flask/app/__init__.py:93]
2025-04-21 16:45:21,087 INFO: project_flask startup [in /var/www/project_flask/app/__init__.py:93]
2025-04-21 16:45:21,251 INFO: project_flask startup [in /var/www/project_flask/app/__init__.py:93]
2025-04-21 16:45:44,949 INFO: project_flask startup [in /var/www/project_flask/app/__init__.py:93]
2025-04-21 16:48:21,146 ERROR: Exception on /auth/reset_password_request [POST] [in /var/www/project_flask/venv/lib/python3.10/site-packages/flask/app.py:838]
Traceback (most recent call last):
  File "/var/www/project_flask/venv/lib/python3.10/site-packages/flask/app.py", line 1473, in wsgi_app
    response = self.full_dispatch_request()
  File "/var/www/project_flask/venv/lib/python3.10/site-packages/flask/app.py", line 882, in full_dispatch_request
    rv = self.handle_user_exception(e)
  File "/var/www/project_flask/venv/lib/python3.10/site-packages/flask/app.py", line 880, in full_dispatch_request
    rv = self.dispatch_request()
  File "/var/www/project_flask/venv/lib/python3.10/site-packages/flask/app.py", line 865, in dispatch_request
    return self.ensure_sync(self.view_functions[rule.endpoint])(**view_args)  # type: ignore[no-any-return]
  File "/var/www/project_flask/app/auth/routes.py", line 64, in reset_password_request
    send_password_reset_email(user)
  File "/var/www/project_flask/app/auth/email.py", line 8, in send_password_reset_email
    sender=app.config['ADMINS'][1],
NameError: name 'app' is not defined
2025-04-21 17:10:42,671 INFO: project_flask startup [in /var/www/project_flask/app/__init__.py:93]
2025-04-21 17:10:42,778 INFO: project_flask startup [in /var/www/project_flask/app/__init__.py:93]
2025-04-21 17:10:42,835 INFO: project_flask startup [in /var/www/project_flask/app/__init__.py:93]
2025-04-21 17:10:55,886 ERROR: Exception on /auth/reset_password_request [POST] [in /var/www/project_flask/venv/lib/python3.10/site-packages/flask/app.py:838]
Traceback (most recent call last):
  File "/var/www/project_flask/venv/lib/python3.10/site-packages/flask/app.py", line 1473, in wsgi_app
    response = self.full_dispatch_request()
  File "/var/www/project_flask/venv/lib/python3.10/site-packages/flask/app.py", line 882, in full_dispatch_request
    rv = self.handle_user_exception(e)
  File "/var/www/project_flask/venv/lib/python3.10/site-packages/flask/app.py", line 880, in full_dispatch_request
    rv = self.dispatch_request()
  File "/var/www/project_flask/venv/lib/python3.10/site-packages/flask/app.py", line 865, in dispatch_request
    return self.ensure_sync(self.view_functions[rule.endpoint])(**view_args)  # type: ignore[no-any-return]
  File "/var/www/project_flask/app/auth/routes.py", line 64, in reset_password_request
    send_password_reset_email(user)
  File "/var/www/project_flask/app/auth/email.py", line 12, in send_password_reset_email
    html_body=render_template('email/reset_password.html',
  File "/var/www/project_flask/venv/lib/python3.10/site-packages/flask/templating.py", line 150, in render_template
    return _render(app, template, context)
  File "/var/www/project_flask/venv/lib/python3.10/site-packages/flask/templating.py", line 131, in _render
    rv = template.render(context)
  File "/var/www/project_flask/venv/lib/python3.10/site-packages/jinja2/environment.py", line 1304, in render
    self.environment.handle_exception()
  File "/var/www/project_flask/venv/lib/python3.10/site-packages/jinja2/environment.py", line 939, in handle_exception
    raise rewrite_traceback_stack(source=source)
  File "/var/www/project_flask/app/templates/email/reset_password.html", line 12, in top-level template code
    <p>{{ url_for('reset_password', token=token, _external=True) }}</p>
  File "/var/www/project_flask/venv/lib/python3.10/site-packages/flask/app.py", line 1084, in url_for
    return self.handle_url_build_error(error, endpoint, values)
  File "/var/www/project_flask/venv/lib/python3.10/site-packages/flask/app.py", line 1073, in url_for
    rv = url_adapter.build(  # type: ignore[union-attr]
  File "/var/www/project_flask/venv/lib/python3.10/site-packages/werkzeug/routing/map.py", line 924, in build
    raise BuildError(endpoint, values, method, self)
werkzeug.routing.exceptions.BuildError: Could not build url for endpoint 'reset_password' with values ['token']. Did you mean 'auth.reset_password' instead?
2025-04-21 17:11:44,672 ERROR: Exception on /auth/reset_password_request [POST] [in /var/www/project_flask/venv/lib/python3.10/site-packages/flask/app.py:838]
Traceback (most recent call last):
  File "/var/www/project_flask/venv/lib/python3.10/site-packages/flask/app.py", line 1473, in wsgi_app
    response = self.full_dispatch_request()
  File "/var/www/project_flask/venv/lib/python3.10/site-packages/flask/app.py", line 882, in full_dispatch_request
    rv = self.handle_user_exception(e)
  File "/var/www/project_flask/venv/lib/python3.10/site-packages/flask/app.py", line 880, in full_dispatch_request
    rv = self.dispatch_request()
  File "/var/www/project_flask/venv/lib/python3.10/site-packages/flask/app.py", line 865, in dispatch_request
    return self.ensure_sync(self.view_functions[rule.endpoint])(**view_args)  # type: ignore[no-any-return]
  File "/var/www/project_flask/app/auth/routes.py", line 64, in reset_password_request
    send_password_reset_email(user)
  File "/var/www/project_flask/app/auth/email.py", line 12, in send_password_reset_email
    html_body=render_template('email/reset_password.html',
  File "/var/www/project_flask/venv/lib/python3.10/site-packages/flask/templating.py", line 150, in render_template
    return _render(app, template, context)
  File "/var/www/project_flask/venv/lib/python3.10/site-packages/flask/templating.py", line 131, in _render
    rv = template.render(context)
  File "/var/www/project_flask/venv/lib/python3.10/site-packages/jinja2/environment.py", line 1304, in render
    self.environment.handle_exception()
  File "/var/www/project_flask/venv/lib/python3.10/site-packages/jinja2/environment.py", line 939, in handle_exception
    raise rewrite_traceback_stack(source=source)
  File "/var/www/project_flask/app/templates/email/reset_password.html", line 12, in top-level template code
    <p>{{ url_for('reset_password', token=token, _external=True) }}</p>
  File "/var/www/project_flask/venv/lib/python3.10/site-packages/flask/app.py", line 1084, in url_for
    return self.handle_url_build_error(error, endpoint, values)
  File "/var/www/project_flask/venv/lib/python3.10/site-packages/flask/app.py", line 1073, in url_for
    rv = url_adapter.build(  # type: ignore[union-attr]
  File "/var/www/project_flask/venv/lib/python3.10/site-packages/werkzeug/routing/map.py", line 924, in build
    raise BuildError(endpoint, values, method, self)
werkzeug.routing.exceptions.BuildError: Could not build url for endpoint 'reset_password' with values ['token']. Did you mean 'auth.reset_password' instead?
2025-04-21 17:15:18,140 INFO: project_flask startup [in /var/www/project_flask/app/__init__.py:93]
2025-04-21 17:15:18,293 INFO: project_flask startup [in /var/www/project_flask/app/__init__.py:93]
2025-04-21 17:15:18,323 INFO: project_flask startup [in /var/www/project_flask/app/__init__.py:93]
